Workbook

Sheet Dashboard
A1: FX Declaration Decision Dashboard
A3: Input Panel | D3: Decision Summary
A4: Date | B4: =Daily_Rate_Input!$A$3 -> -180686 | D4: Best Route | E4: {=IF(Route_Comparison!$C$5="Yes",INDEX(Route_Comparison!$B$3:$B$5,MATCH(MIN(Route_Comparison!$G$3:$G$5),Route_Comparison!$G$3:$G$5,0)),INDEX(Route_Comparison!$B$3:$B$4,MATCH(MIN(Route_Comparison!$G$3:$G$4),Route_Comparison!$G$3:$G$4,0)))} -> اظهارنامه با ارز از مسیر دوبی | G4: Use Daily_Report to compare all origin currencies at once. Use History to paste daily snapshots for trend tracking.
A5: Amount USD | B5: 1000000 | D5: Best Cost % | E5: =IF(Route_Comparison!$C$5="Yes",MIN(Route_Comparison!$G$3:$G$5),MIN(Route_Comparison!$G$3:$G$4)) -> 0.005
A6: Origin Currency | B6: USD_Istanbul | D6: Cost Amount USD | E6: =B5*E5 -> 5000
A7: No-FX Fee % | B7: =Fees_Settings!$E$3 -> 0.007 | D7: Second Best Cost % | E7: =IF(Route_Comparison!$C$5="Yes",SMALL(Route_Comparison!$G$3:$G$5,2),MAX(Route_Comparison!$G$3:$G$4)) -> 0.005912748
A8: Dubai Transfer Fee % | B8: =Fees_Settings!$E$4 -> 0.005 | D8: Saving vs Second Best % | E8: =E7-E5 -> 0.00091274803
A9: Istanbul Direct Fee % | B9: =Fees_Settings!$E$5 -> 0.015
A10: Notes | B10: Manual fees are percent-based. Example: enter 0.70% not 7. Origin codes: USD_Istanbul, AED_Dubai, etc. | D10: {="بهترین مسیر امروز برای رفع تعهد با منشأ ارز "&XLOOKUP($B$6,Daily_Rates!$B$3:$B$7,Daily_Rates!$C$3:$C$7)&"، «"&$E$4&"» است."&CHAR(10)& "هزینه تمام‌شده این مسیر "&TEXT($E$5,"0.00%")&" معادل حدود "&TEXT($E$6,"#,##0")&" دلار است."&CHAR(10)&CHAR(10)& "جزئیات مسیر پیشنهادی:"&CHAR(10)& IF($E$4="اظهارنامه بدون ارز", "مشتری "&TEXT(XLOOKUP("NO_FX",Route_Comparison!$A$3:$A$5,Route_Comparison!$F$3:$F$5),"0.00%")&" هزینه کارمزد اظهارنامه بدون ارز پرداخت می‌کند و "&IF(XLOOKUP("NO_FX",Route_Comparison!$A$3:$A$5,Route_Comparison!$E$3:$E$5)<0,TEXT(ABS(XLOOKUP("NO_FX",Route_Comparison!$A$3:$A$5,Route_Comparison!$E$3:$E$5)),"0.00%")&" بابت تبدیل "&XLOOKUP($B$6,Daily_Rates!$B$3:$B$7,Daily_Rates!$C$3:$C$7)&" به دلار تهران سر می‌گیرد",TEXT(XLOOKUP("NO_FX",Route_Comparison!$A$3:$A$5,Route_Comparison!$E$3:$E$5),"0.00%")&" بابت تبدیل "&XLOOKUP($B$6,Daily_Rates!$B$3:$B$7,Daily_Rates!$C$3:$C$7)&" به دلار تهران هزینه می‌دهد")&"؛ بنابراین هزینه نهایی "&TEXT(XLOOKUP("NO_FX",Route_Comparison!$A$3:$A$5,Route_Comparison!$G$3:$G$5),"0.00%")&" می‌شود.", IF($E$4="اظهارنامه با ارز از مسیر دوبی", "مشتری "&IF(XLOOKUP("DUBAI_FX",Route_Comparison!$A$3:$A$5,Route_Comparison!$E$3:$E$5)<0,TEXT(ABS(XLOOKUP("DUBAI_FX",Route_Comparison!$A$3:$A$5,Route_Comparison!$E$3:$E$5)),"0.00%")&" بابت تبدیل "&XLOOKUP($B$6,Daily_Rates!$B$3:$B$7,Daily_Rates!$C$3:$C$7)&" به دلار دوبی سر می‌گیرد",TEXT(XLOOKUP("DUBAI_FX",Route_Comparison!$A$3:$A$5,Route_Comparison!$E$3:$E$5),"0.00%")&" بابت تبدیل "&XLOOKUP($B$6,Daily_Rates!$B$3:$B$7,Daily_Rates!$C$3:$C$7)&" به دلار دوبی هزینه می‌دهد")&" و "&TEXT(XLOOKUP("DUBAI_FX",Route_Comparison!$A$3:$A$5,Route_Comparison!$F$3:$F$5),"0.00%")&" هزینه انتقال / ورود ارز از مسیر دوبی پرداخت می‌کند؛ بنابراین هزینه نهایی "&TEXT(XLOOKUP("DUBAI_FX",Route_Comparison!$A$3:$A$5,Route_Comparison!$G$3:$G$5),"0.00%")&" می‌شود.", "مشتری از مسیر مستقیم استانبول استفاده می‌کند. این مسیر شامل تبدیل ارز و هزینه انتقال است و کارمزد ثابت آن "&TEXT(XLOOKUP("IST_DIRECT",Route_Comparison!$A$3:$A$5,Route_Comparison!$G$3:$G$5),"0.00%")&" است." ))&CHAR(10)&CHAR(10)& "گزینه‌های بعدی شامل:"&CHAR(10)& IF(AND($E$4<>"اظهارنامه بدون ارز",XLOOKUP("NO_FX",Route_Comparison!$A$3:$A$5,Route_Comparison!$C$3:$C$5)="Yes"),"- اظهارنامه بدون ارز: هزینه تمام‌شده "&TEXT(XLOOKUP("NO_FX",Route_Comparison!$A$3:$A$5,Route_Comparison!$G$3:$G$5),"0.00%")&" معادل حدود "&TEXT(XLOOKUP("NO_FX",Route_Comparison!$A$3:$A$5,Route_Comparison!$H$3:$H$5),"#,##0")&" دلار. شامل "&TEXT(XLOOKUP("NO_FX",Route_Comparison!$A$3:$A$5,Route_Comparison!$F$3:$F$5),"0.00%")&" کارمزد اظهارنامه بدون ارز و "&IF(XLOOKUP("NO_FX",Route_Comparison!$A$3:$A$5,Route_Comparison!$E$3:$E$5)<0,TEXT(ABS(XLOOKUP("NO_FX",Route_Comparison!$A$3:$A$5,Route_Comparison!$E$3:$E$5)),"0.00%")&" سرگیری از تبدیل "&XLOOKUP($B$6,Daily_Rates!$B$3:$B$7,Daily_Rates!$C$3:$C$7)&" به دلار تهران",TEXT(XLOOKUP("NO_FX",Route_Comparison!$A$3:$A$5,Route_Comparison!$E$3:$E$5),"0.00%")&" هزینه تبدیل "&XLOOKUP($B$6,Daily_Rates!$B$3:$B$7,Daily_Rates!$C$3:$C$7)&" به دلار تهران")&"."&CHAR(10),"")& IF(AND($E$4<>"اظهارنامه با ارز از مسیر دوبی",XLOOKUP("DUBAI_FX",Route_Comparison!$A$3:$A$5,Route_Comparison!$C$3:$C$5)="Yes"),"- اظهارنامه با ارز از مسیر دوبی: هزینه تمام‌شده "&TEXT(XLOOKUP("DUBAI_FX",Route_Comparison!$A$3:$A$5,Route_Comparison!$G$3:$G$5),"0.00%")&" معادل حدود "&TEXT(XLOOKUP("DUBAI_FX",Route_Comparison!$A$3:$A$5,Route_Comparison!$H$3:$H$5),"#,##0")&" دلار. شامل "&TEXT(XLOOKUP("DUBAI_FX",Route_Comparison!$A$3:$A$5,Route_Comparison!$E$3:$E$5),"0.00%")&" هزینه تبدیل "&XLOOKUP($B$6,Daily_Rates!$B$3:$B$7,Daily_Rates!$C$3:$C$7)&" به دلار دوبی و "&TEXT(XLOOKUP("DUBAI_FX",Route_Comparison!$A$3:$A$5,Route_Comparison!$F$3:$F$5),"0.00%")&" هزینه انتقال / ورود ارز از مسیر دوبی."&CHAR(10),"")& IF(AND($E$4<>"اظهارنامه با ارز مستقیم استانبول",XLOOKUP("IST_DIRECT",Route_Comparison!$A$3:$A$5,Route_Comparison!$C$3:$C$5)="Yes"),"- اظهارنامه با ارز مستقیم استانبول: هزینه تمام‌شده "&TEXT(XLOOKUP("IST_DIRECT",Route_Comparison!$A$3:$A$5,Route_Comparison!$G$3:$G$5),"0.00%")&" معادل حدود "&TEXT(XLOOKUP("IST_DIRECT",Route_Comparison!$A$3:$A$5,Route_Comparison!$H$3:$H$5),"#,##0")&" دلار. این مسیر شامل تبدیل ارز و هزینه انتقال با کارمزد ثابت تأمین‌کننده است.","")} -> بهترین مسیر امروز برای رفع تعهد با منشأ ارز دلار استانبول، «اظهارنامه با ارز از مسیر دوبی» است. هزینه تمام‌شده این مسیر 0.50% معادل حدود 5,000 دلار است. جزئیات مسیر پیشنهادی: مشتری بابت تبدیل دلار استانبول به دلار دوبی هزینه می‌دهد و 0.50% هزینه انتقال / ورود ارز از مسیر دوبی پرداخت می‌کند؛ بنابراین هزینه نهایی 0.50% می‌شود. گزینه‌های بعدی شامل: - اظهارنامه بدون ارز: هزینه تمام‌شده 0.59% معادل حدود 5,913 دلار. شامل 0.70% کارمزد اظهارنامه بدون ارز و 0.11% سرگیری از تبدیل دلار استانبول به دلار تهران. - اظهارنامه با ارز مستقیم استانبول: هزینه تمام‌شده 1.50% معادل حدود 15,000 دلار. این مسیر شامل تبدیل ارز و هزینه انتقال با کارمزد ثابت تأمین‌کننده است.
A11: Use Manual Origin→Tehran? | B11: No
A12: Manual Origin→Tehran Cost % | D12: Market | E12: Origin Code | F12: Origin Label | G12: Buy | H12: Sell | I12: Spread %
A13: Use Manual Origin→Dubai? | B13: No | D13: =Daily_Rates!A3 -> Tether | E13: =Daily_Rates!B3 -> USD_Tether | F13: =Daily_Rates!C3 -> دلار تتر | G13: =Daily_Rates!D3 -> 3.665 | H13: =Daily_Rates!E3 -> 3.67 | I13: =(H13-G13)/G13 -> 0.0013642565
A14: Manual Origin→Dubai Cost % | D14: =Daily_Rates!A4 -> Tehran | E14: =Daily_Rates!B4 -> USD_Tehran | F14: =Daily_Rates!C4 -> دلار تهران | G14: =Daily_Rates!D4 -> 3.665 | H14: =Daily_Rates!E4 -> 3.675 | I14: =(H14-G14)/G14 -> 0.002728513
D15: =Daily_Rates!A5 -> Istanbul | E15: =Daily_Rates!B5 -> USD_Istanbul | F15: =Daily_Rates!C5 -> دلار استانبول | G15: =Daily_Rates!D5 -> 3.679 | H15: =Daily_Rates!E5 -> 3.685 | I15: =(H15-G15)/G15 -> 0.001630878
D16: =Daily_Rates!A6 -> Sulaymaniyah | E16: =Daily_Rates!B6 -> USD_Sulaymaniyah | F16: =Daily_Rates!C6 -> دلار سلیمانیه | G16: =Daily_Rates!D6 -> - | H16: =Daily_Rates!E6 -> - | I16: =(H16-G16)/G16 -> #VALUE!
D17: =Daily_Rates!A7 -> Dubai | E17: =Daily_Rates!B7 -> AED_Dubai | F17: =Daily_Rates!C7 -> درهم دوبی | G17: =Daily_Rates!D7 -> - | H17: =Daily_Rates!E7 -> - | I17: =(H17-G17)/G17 -> #VALUE!
A19: Route ID | B19: Route Name | C19: Active? | D19: Auto Conv % | E19: Effective Conv % | F19: Fee % | G19: Total Cost % | H19: Cost Amount USD | I19: Notes
A20: =Route_Comparison!A3 -> NO_FX | B20: =Route_Comparison!B3 -> اظهارنامه بدون ارز | C20: =Route_Comparison!C3 -> Yes | D20: =Route_Comparison!D3 -> -0.001087252 | E20: =Route_Comparison!E3 -> -0.001087252 | F20: =Route_Comparison!F3 -> 0.007 | G20: =IF(Route_Comparison!G3="","",Route_Comparison!G3) -> 0.005912748 | H20: =IF(Route_Comparison!H3="","",Route_Comparison!H3) -> 5912.748 | I20: =Route_Comparison!I3 -> Origin → USD_Tehran + No-FX declaration
A21: =Route_Comparison!A4 -> DUBAI_FX | B21: =Route_Comparison!B4 -> اظهارنامه با ارز از مسیر دوبی | C21: =Route_Comparison!C4 -> Yes | D21: =Route_Comparison!D4 | E21: =Route_Comparison!E4 | F21: =Route_Comparison!F4 -> 0.005 | G21: =IF(Route_Comparison!G4="","",Route_Comparison!G4) -> 0.005 | H21: =IF(Route_Comparison!H4="","",Route_Comparison!H4) -> 5000 | I21: =Route_Comparison!I4 -> Origin → USD_Dubai + Dubai transfer/import fee
A22: =Route_Comparison!A5 -> IST_DIRECT | B22: =Route_Comparison!B5 -> اظهارنامه با ارز مستقیم استانبول | C22: =Route_Comparison!C5 -> Yes | D22: =Route_Comparison!D5 -> 0 | E22: =Route_Comparison!E5 -> 0 | F22: =Route_Comparison!F5 -> 0.015 | G22: =IF(Route_Comparison!G5="","",Route_Comparison!G5) -> 0.015 | H22: =IF(Route_Comparison!H5="","",Route_Comparison!H5) -> 15000 | I22: =Route_Comparison!I5 -> Only active when Origin = USD_Istanbul

Sheet Daily_Rates
A1: Daily AED-Based Market Rates — Auto from Daily_Rate_Input
A2: Market_EN | B2: Origin_Code | C2: Origin_Label_FA | D2: Buy | E2: Sell | F2: Notes
A3: Tether | B3: USD_Tether | C3: دلار تتر | D3: {=IFERROR(XLOOKUP(A3,Daily_Rate_Input!$B$3:$B$7,Daily_Rate_Input!$C$3:$C$7),"")} -> 3.665 | E3: {=IFERROR(XLOOKUP(A3,Daily_Rate_Input!$B$3:$B$7,Daily_Rate_Input!$D$3:$D$7),"")} -> 3.67 | F3: {=IFERROR(XLOOKUP(A3,Daily_Rate_Input!$B$3:$B$7,Daily_Rate_Input!$E$3:$E$7),"")} -> Paste/overwrite this block daily
A4: Tehran | B4: USD_Tehran | C4: دلار تهران | D4: {=IFERROR(XLOOKUP(A4,Daily_Rate_Input!$B$3:$B$7,Daily_Rate_Input!$C$3:$C$7),"")} -> 3.665 | E4: {=IFERROR(XLOOKUP(A4,Daily_Rate_Input!$B$3:$B$7,Daily_Rate_Input!$D$3:$D$7),"")} -> 3.675 | F4: {=IFERROR(XLOOKUP(A4,Daily_Rate_Input!$B$3:$B$7,Daily_Rate_Input!$E$3:$E$7),"")}
A5: Istanbul | B5: USD_Istanbul | C5: دلار استانبول | D5: {=IFERROR(XLOOKUP(A5,Daily_Rate_Input!$B$3:$B$7,Daily_Rate_Input!$C$3:$C$7),"")} -> 3.679 | E5: {=IFERROR(XLOOKUP(A5,Daily_Rate_Input!$B$3:$B$7,Daily_Rate_Input!$D$3:$D$7),"")} -> 3.685 | F5: {=IFERROR(XLOOKUP(A5,Daily_Rate_Input!$B$3:$B$7,Daily_Rate_Input!$E$3:$E$7),"")}
A6: Sulaymaniyah | B6: USD_Sulaymaniyah | C6: دلار سلیمانیه | D6: {=IFERROR(XLOOKUP(A6,Daily_Rate_Input!$B$3:$B$7,Daily_Rate_Input!$C$3:$C$7),"")} -> - | E6: {=IFERROR(XLOOKUP(A6,Daily_Rate_Input!$B$3:$B$7,Daily_Rate_Input!$D$3:$D$7),"")} -> - | F6: {=IFERROR(XLOOKUP(A6,Daily_Rate_Input!$B$3:$B$7,Daily_Rate_Input!$E$3:$E$7),"")}
A7: Dubai | B7: AED_Dubai | C7: درهم دوبی | D7: {=IFERROR(XLOOKUP(A7,Daily_Rate_Input!$B$3:$B$7,Daily_Rate_Input!$C$3:$C$7),"")} -> - | E7: {=IFERROR(XLOOKUP(A7,Daily_Rate_Input!$B$3:$B$7,Daily_Rate_Input!$D$3:$D$7),"")} -> - | F7: {=IFERROR(XLOOKUP(A7,Daily_Rate_Input!$B$3:$B$7,Daily_Rate_Input!$E$3:$E$7),"")} -> AED origin; USD Dubai conversion uses Dubai spread

Sheet Fees_Settings
A1: Fee Settings & Route Defaults (Percent Inputs)
A2: Fee Item | B2: Default % | C2: Manual Override % | D2: Use Manual? | E2: Effective %
A3: No-FX Declaration Fee | B3: 0.007 | D3: No | E3: =IF(D3="Yes",C3,B3) -> 0.007
A4: Dubai Transfer / Import Fee | B4: 0.005 | D4: No | E4: =IF(D4="Yes",C4,B4) -> 0.005
A5: Istanbul Direct Supplier Fee | B5: 0.015 | D5: No | E5: =IF(D5="Yes",C5,B5) -> 0.015

Sheet Conversion_Matrix
A1: Conversion Cost Matrix (%)
A2: From \ To | B2: USD_Tether | C2: USD_Tehran | D2: USD_Istanbul | E2: USD_Sulaymaniyah | F2: USD_Dubai
A3: USD_Tether | B3: {=iferror(IF(LEFT($A3,4)="AED_",(XLOOKUP(SUBSTITUTE(B$2,"USD_",""),Daily_Rates!$A$3:$A$7,Daily_Rates!$E$3:$E$7)-XLOOKUP(SUBSTITUTE(B$2,"USD_",""),Daily_Rates!$A$3:$A$7,Daily_Rates!$D$3:$D$7))/XLOOKUP(SUBSTITUTE(B$2,"USD_",""),Daily_Rates!$A$3:$A$7,Daily_Rates!$D$3:$D$7),IF($A3=B$2,0,(XLOOKUP(SUBSTITUTE(B$2,"USD_",""),Daily_Rates!$A$3:$A$7,Daily_Rates!$E$3:$E$7)-XLOOKUP(SUBSTITUTE($A3,"USD_",""),Daily_Rates!$A$3:$A$7,Daily_Rates!$D$3:$D$7))/XLOOKUP(SUBSTITUTE($A3,"USD_",""),Daily_Rates!$A$3:$A$7,Daily_Rates!$D$3:$D$7))),"")} -> 0 | C3: {=iferror(IF(LEFT($A3,4)="AED_",(XLOOKUP(SUBSTITUTE(C$2,"USD_",""),Daily_Rates!$A$3:$A$7,Daily_Rates!$E$3:$E$7)-XLOOKUP(SUBSTITUTE(C$2,"USD_",""),Daily_Rates!$A$3:$A$7,Daily_Rates!$D$3:$D$7))/XLOOKUP(SUBSTITUTE(C$2,"USD_",""),Daily_Rates!$A$3:$A$7,Daily_Rates!$D$3:$D$7),IF($A3=C$2,0,(XLOOKUP(SUBSTITUTE(C$2,"USD_",""),Daily_Rates!$A$3:$A$7,Daily_Rates!$E$3:$E$7)-XLOOKUP(SUBSTITUTE($A3,"USD_",""),Daily_Rates!$A$3:$A$7,Daily_Rates!$D$3:$D$7))/XLOOKUP(SUBSTITUTE($A3,"USD_",""),Daily_Rates!$A$3:$A$7,Daily_Rates!$D$3:$D$7))),"")} -> 0.002728513 | D3: {=iferror(IF(LEFT($A3,4)="AED_",(XLOOKUP(SUBSTITUTE(D$2,"USD_",""),Daily_Rates!$A$3:$A$7,Daily_Rates!$E$3:$E$7)-XLOOKUP(SUBSTITUTE(D$2,"USD_",""),Daily_Rates!$A$3:$A$7,Daily_Rates!$D$3:$D$7))/XLOOKUP(SUBSTITUTE(D$2,"USD_",""),Daily_Rates!$A$3:$A$7,Daily_Rates!$D$3:$D$7),IF($A3=D$2,0,(XLOOKUP(SUBSTITUTE(D$2,"USD_",""),Daily_Rates!$A$3:$A$7,Daily_Rates!$E$3:$E$7)-XLOOKUP(SUBSTITUTE($A3,"USD_",""),Daily_Rates!$A$3:$A$7,Daily_Rates!$D$3:$D$7))/XLOOKUP(SUBSTITUTE($A3,"USD_",""),Daily_Rates!$A$3:$A$7,Daily_Rates!$D$3:$D$7))),"")} -> 0.0054570259 | E3: {=iferror(IF(LEFT($A3,4)="AED_",(XLOOKUP(SUBSTITUTE(E$2,"USD_",""),Daily_Rates!$A$3:$A$7,Daily_Rates!$E$3:$E$7)-XLOOKUP(SUBSTITUTE(E$2,"USD_",""),Daily_Rates!$A$3:$A$7,Daily_Rates!$D$3:$D$7))/XLOOKUP(SUBSTITUTE(E$2,"USD_",""),Daily_Rates!$A$3:$A$7,Daily_Rates!$D$3:$D$7),IF($A3=E$2,0,(XLOOKUP(SUBSTITUTE(E$2,"USD_",""),Daily_Rates!$A$3:$A$7,Daily_Rates!$E$3:$E$7)-XLOOKUP(SUBSTITUTE($A3,"USD_",""),Daily_Rates!$A$3:$A$7,Daily_Rates!$D$3:$D$7))/XLOOKUP(SUBSTITUTE($A3,"USD_",""),Daily_Rates!$A$3:$A$7,Daily_Rates!$D$3:$D$7))),"")} | F3: {=iferror(IF(LEFT($A3,4)="AED_",(XLOOKUP(SUBSTITUTE(F$2,"USD_",""),Daily_Rates!$A$3:$A$7,Daily_Rates!$E$3:$E$7)-XLOOKUP(SUBSTITUTE(F$2,"USD_",""),Daily_Rates!$A$3:$A$7,Daily_Rates!$D$3:$D$7))/XLOOKUP(SUBSTITUTE(F$2,"USD_",""),Daily_Rates!$A$3:$A$7,Daily_Rates!$D$3:$D$7),IF($A3=F$2,0,(XLOOKUP(SUBSTITUTE(F$2,"USD_",""),Daily_Rates!$A$3:$A$7,Daily_Rates!$E$3:$E$7)-XLOOKUP(SUBSTITUTE($A3,"USD_",""),Daily_Rates!$A$3:$A$7,Daily_Rates!$D$3:$D$7))/XLOOKUP(SUBSTITUTE($A3,"USD_",""),Daily_Rates!$A$3:$A$7,Daily_Rates!$D$3:$D$7))),"")}
A4: USD_Tehran | B4: {=iferror(IF(LEFT($A4,4)="AED_",(XLOOKUP(SUBSTITUTE(B$2,"USD_",""),Daily_Rates!$A$3:$A$7,Daily_Rates!$E$3:$E$7)-XLOOKUP(SUBSTITUTE(B$2,"USD_",""),Daily_Rates!$A$3:$A$7,Daily_Rates!$D$3:$D$7))/XLOOKUP(SUBSTITUTE(B$2,"USD_",""),Daily_Rates!$A$3:$A$7,Daily_Rates!$D$3:$D$7),IF($A4=B$2,0,(XLOOKUP(SUBSTITUTE(B$2,"USD_",""),Daily_Rates!$A$3:$A$7,Daily_Rates!$E$3:$E$7)-XLOOKUP(SUBSTITUTE($A4,"USD_",""),Daily_Rates!$A$3:$A$7,Daily_Rates!$D$3:$D$7))/XLOOKUP(SUBSTITUTE($A4,"USD_",""),Daily_Rates!$A$3:$A$7,Daily_Rates!$D$3:$D$7))),"")} -> 0.0013642565 | C4: {=iferror(IF(LEFT($A4,4)="AED_",(XLOOKUP(SUBSTITUTE(C$2,"USD_",""),Daily_Rates!$A$3:$A$7,Daily_Rates!$E$3:$E$7)-XLOOKUP(SUBSTITUTE(C$2,"USD_",""),Daily_Rates!$A$3:$A$7,Daily_Rates!$D$3:$D$7))/XLOOKUP(SUBSTITUTE(C$2,"USD_",""),Daily_Rates!$A$3:$A$7,Daily_Rates!$D$3:$D$7),IF($A4=C$2,0,(XLOOKUP(SUBSTITUTE(C$2,"USD_",""),Daily_Rates!$A$3:$A$7,Daily_Rates!$E$3:$E$7)-XLOOKUP(SUBSTITUTE($A4,"USD_",""),Daily_Rates!$A$3:$A$7,Daily_Rates!$D$3:$D$7))/XLOOKUP(SUBSTITUTE($A4,"USD_",""),Daily_Rates!$A$3:$A$7,Daily_Rates!$D$3:$D$7))),"")} -> 0 | D4: {=iferror(IF(LEFT($A4,4)="AED_",(XLOOKUP(SUBSTITUTE(D$2,"USD_",""),Daily_Rates!$A$3:$A$7,Daily_Rates!$E$3:$E$7)-XLOOKUP(SUBSTITUTE(D$2,"USD_",""),Daily_Rates!$A$3:$A$7,Daily_Rates!$D$3:$D$7))/XLOOKUP(SUBSTITUTE(D$2,"USD_",""),Daily_Rates!$A$3:$A$7,Daily_Rates!$D$3:$D$7),IF($A4=D$2,0,(XLOOKUP(SUBSTITUTE(D$2,"USD_",""),Daily_Rates!$A$3:$A$7,Daily_Rates!$E$3:$E$7)-XLOOKUP(SUBSTITUTE($A4,"USD_",""),Daily_Rates!$A$3:$A$7,Daily_Rates!$D$3:$D$7))/XLOOKUP(SUBSTITUTE($A4,"USD_",""),Daily_Rates!$A$3:$A$7,Daily_Rates!$D$3:$D$7))),"")} -> 0.0054570259 | E4: {=iferror(IF(LEFT($A4,4)="AED_",(XLOOKUP(SUBSTITUTE(E$2,"USD_",""),Daily_Rates!$A$3:$A$7,Daily_Rates!$E$3:$E$7)-XLOOKUP(SUBSTITUTE(E$2,"USD_",""),Daily_Rates!$A$3:$A$7,Daily_Rates!$D$3:$D$7))/XLOOKUP(SUBSTITUTE(E$2,"USD_",""),Daily_Rates!$A$3:$A$7,Daily_Rates!$D$3:$D$7),IF($A4=E$2,0,(XLOOKUP(SUBSTITUTE(E$2,"USD_",""),Daily_Rates!$A$3:$A$7,Daily_Rates!$E$3:$E$7)-XLOOKUP(SUBSTITUTE($A4,"USD_",""),Daily_Rates!$A$3:$A$7,Daily_Rates!$D$3:$D$7))/XLOOKUP(SUBSTITUTE($A4,"USD_",""),Daily_Rates!$A$3:$A$7,Daily_Rates!$D$3:$D$7))),"")} | F4: {=iferror(IF(LEFT($A4,4)="AED_",(XLOOKUP(SUBSTITUTE(F$2,"USD_",""),Daily_Rates!$A$3:$A$7,Daily_Rates!$E$3:$E$7)-XLOOKUP(SUBSTITUTE(F$2,"USD_",""),Daily_Rates!$A$3:$A$7,Daily_Rates!$D$3:$D$7))/XLOOKUP(SUBSTITUTE(F$2,"USD_",""),Daily_Rates!$A$3:$A$7,Daily_Rates!$D$3:$D$7),IF($A4=F$2,0,(XLOOKUP(SUBSTITUTE(F$2,"USD_",""),Daily_Rates!$A$3:$A$7,Daily_Rates!$E$3:$E$7)-XLOOKUP(SUBSTITUTE($A4,"USD_",""),Daily_Rates!$A$3:$A$7,Daily_Rates!$D$3:$D$7))/XLOOKUP(SUBSTITUTE($A4,"USD_",""),Daily_Rates!$A$3:$A$7,Daily_Rates!$D$3:$D$7))),"")}
A5: USD_Istanbul | B5: {=iferror(IF(LEFT($A5,4)="AED_",(XLOOKUP(SUBSTITUTE(B$2,"USD_",""),Daily_Rates!$A$3:$A$7,Daily_Rates!$E$3:$E$7)-XLOOKUP(SUBSTITUTE(B$2,"USD_",""),Daily_Rates!$A$3:$A$7,Daily_Rates!$D$3:$D$7))/XLOOKUP(SUBSTITUTE(B$2,"USD_",""),Daily_Rates!$A$3:$A$7,Daily_Rates!$D$3:$D$7),IF($A5=B$2,0,(XLOOKUP(SUBSTITUTE(B$2,"USD_",""),Daily_Rates!$A$3:$A$7,Daily_Rates!$E$3:$E$7)-XLOOKUP(SUBSTITUTE($A5,"USD_",""),Daily_Rates!$A$3:$A$7,Daily_Rates!$D$3:$D$7))/XLOOKUP(SUBSTITUTE($A5,"USD_",""),Daily_Rates!$A$3:$A$7,Daily_Rates!$D$3:$D$7))),"")} -> -0.0024463169 | C5: {=iferror(IF(LEFT($A5,4)="AED_",(XLOOKUP(SUBSTITUTE(C$2,"USD_",""),Daily_Rates!$A$3:$A$7,Daily_Rates!$E$3:$E$7)-XLOOKUP(SUBSTITUTE(C$2,"USD_",""),Daily_Rates!$A$3:$A$7,Daily_Rates!$D$3:$D$7))/XLOOKUP(SUBSTITUTE(C$2,"USD_",""),Daily_Rates!$A$3:$A$7,Daily_Rates!$D$3:$D$7),IF($A5=C$2,0,(XLOOKUP(SUBSTITUTE(C$2,"USD_",""),Daily_Rates!$A$3:$A$7,Daily_Rates!$E$3:$E$7)-XLOOKUP(SUBSTITUTE($A5,"USD_",""),Daily_Rates!$A$3:$A$7,Daily_Rates!$D$3:$D$7))/XLOOKUP(SUBSTITUTE($A5,"USD_",""),Daily_Rates!$A$3:$A$7,Daily_Rates!$D$3:$D$7))),"")} -> -0.001087252 | D5: {=iferror(IF(LEFT($A5,4)="AED_",(XLOOKUP(SUBSTITUTE(D$2,"USD_",""),Daily_Rates!$A$3:$A$7,Daily_Rates!$E$3:$E$7)-XLOOKUP(SUBSTITUTE(D$2,"USD_",""),Daily_Rates!$A$3:$A$7,Daily_Rates!$D$3:$D$7))/XLOOKUP(SUBSTITUTE(D$2,"USD_",""),Daily_Rates!$A$3:$A$7,Daily_Rates!$D$3:$D$7),IF($A5=D$2,0,(XLOOKUP(SUBSTITUTE(D$2,"USD_",""),Daily_Rates!$A$3:$A$7,Daily_Rates!$E$3:$E$7)-XLOOKUP(SUBSTITUTE($A5,"USD_",""),Daily_Rates!$A$3:$A$7,Daily_Rates!$D$3:$D$7))/XLOOKUP(SUBSTITUTE($A5,"USD_",""),Daily_Rates!$A$3:$A$7,Daily_Rates!$D$3:$D$7))),"")} -> 0 | E5: {=iferror(IF(LEFT($A5,4)="AED_",(XLOOKUP(SUBSTITUTE(E$2,"USD_",""),Daily_Rates!$A$3:$A$7,Daily_Rates!$E$3:$E$7)-XLOOKUP(SUBSTITUTE(E$2,"USD_",""),Daily_Rates!$A$3:$A$7,Daily_Rates!$D$3:$D$7))/XLOOKUP(SUBSTITUTE(E$2,"USD_",""),Daily_Rates!$A$3:$A$7,Daily_Rates!$D$3:$D$7),IF($A5=E$2,0,(XLOOKUP(SUBSTITUTE(E$2,"USD_",""),Daily_Rates!$A$3:$A$7,Daily_Rates!$E$3:$E$7)-XLOOKUP(SUBSTITUTE($A5,"USD_",""),Daily_Rates!$A$3:$A$7,Daily_Rates!$D$3:$D$7))/XLOOKUP(SUBSTITUTE($A5,"USD_",""),Daily_Rates!$A$3:$A$7,Daily_Rates!$D$3:$D$7))),"")} | F5: {=iferror(IF(LEFT($A5,4)="AED_",(XLOOKUP(SUBSTITUTE(F$2,"USD_",""),Daily_Rates!$A$3:$A$7,Daily_Rates!$E$3:$E$7)-XLOOKUP(SUBSTITUTE(F$2,"USD_",""),Daily_Rates!$A$3:$A$7,Daily_Rates!$D$3:$D$7))/XLOOKUP(SUBSTITUTE(F$2,"USD_",""),Daily_Rates!$A$3:$A$7,Daily_Rates!$D$3:$D$7),IF($A5=F$2,0,(XLOOKUP(SUBSTITUTE(F$2,"USD_",""),Daily_Rates!$A$3:$A$7,Daily_Rates!$E$3:$E$7)-XLOOKUP(SUBSTITUTE($A5,"USD_",""),Daily_Rates!$A$3:$A$7,Daily_Rates!$D$3:$D$7))/XLOOKUP(SUBSTITUTE($A5,"USD_",""),Daily_Rates!$A$3:$A$7,Daily_Rates!$D$3:$D$7))),"")}
A6: USD_Sulaymaniyah | B6: {=iferror(IF(LEFT($A6,4)="AED_",(XLOOKUP(SUBSTITUTE(B$2,"USD_",""),Daily_Rates!$A$3:$A$7,Daily_Rates!$E$3:$E$7)-XLOOKUP(SUBSTITUTE(B$2,"USD_",""),Daily_Rates!$A$3:$A$7,Daily_Rates!$D$3:$D$7))/XLOOKUP(SUBSTITUTE(B$2,"USD_",""),Daily_Rates!$A$3:$A$7,Daily_Rates!$D$3:$D$7),IF($A6=B$2,0,(XLOOKUP(SUBSTITUTE(B$2,"USD_",""),Daily_Rates!$A$3:$A$7,Daily_Rates!$E$3:$E$7)-XLOOKUP(SUBSTITUTE($A6,"USD_",""),Daily_Rates!$A$3:$A$7,Daily_Rates!$D$3:$D$7))/XLOOKUP(SUBSTITUTE($A6,"USD_",""),Daily_Rates!$A$3:$A$7,Daily_Rates!$D$3:$D$7))),"")} | C6: {=iferror(IF(LEFT($A6,4)="AED_",(XLOOKUP(SUBSTITUTE(C$2,"USD_",""),Daily_Rates!$A$3:$A$7,Daily_Rates!$E$3:$E$7)-XLOOKUP(SUBSTITUTE(C$2,"USD_",""),Daily_Rates!$A$3:$A$7,Daily_Rates!$D$3:$D$7))/XLOOKUP(SUBSTITUTE(C$2,"USD_",""),Daily_Rates!$A$3:$A$7,Daily_Rates!$D$3:$D$7),IF($A6=C$2,0,(XLOOKUP(SUBSTITUTE(C$2,"USD_",""),Daily_Rates!$A$3:$A$7,Daily_Rates!$E$3:$E$7)-XLOOKUP(SUBSTITUTE($A6,"USD_",""),Daily_Rates!$A$3:$A$7,Daily_Rates!$D$3:$D$7))/XLOOKUP(SUBSTITUTE($A6,"USD_",""),Daily_Rates!$A$3:$A$7,Daily_Rates!$D$3:$D$7))),"")} | D6: {=iferror(IF(LEFT($A6,4)="AED_",(XLOOKUP(SUBSTITUTE(D$2,"USD_",""),Daily_Rates!$A$3:$A$7,Daily_Rates!$E$3:$E$7)-XLOOKUP(SUBSTITUTE(D$2,"USD_",""),Daily_Rates!$A$3:$A$7,Daily_Rates!$D$3:$D$7))/XLOOKUP(SUBSTITUTE(D$2,"USD_",""),Daily_Rates!$A$3:$A$7,Daily_Rates!$D$3:$D$7),IF($A6=D$2,0,(XLOOKUP(SUBSTITUTE(D$2,"USD_",""),Daily_Rates!$A$3:$A$7,Daily_Rates!$E$3:$E$7)-XLOOKUP(SUBSTITUTE($A6,"USD_",""),Daily_Rates!$A$3:$A$7,Daily_Rates!$D$3:$D$7))/XLOOKUP(SUBSTITUTE($A6,"USD_",""),Daily_Rates!$A$3:$A$7,Daily_Rates!$D$3:$D$7))),"")} | E6: {=iferror(IF(LEFT($A6,4)="AED_",(XLOOKUP(SUBSTITUTE(E$2,"USD_",""),Daily_Rates!$A$3:$A$7,Daily_Rates!$E$3:$E$7)-XLOOKUP(SUBSTITUTE(E$2,"USD_",""),Daily_Rates!$A$3:$A$7,Daily_Rates!$D$3:$D$7))/XLOOKUP(SUBSTITUTE(E$2,"USD_",""),Daily_Rates!$A$3:$A$7,Daily_Rates!$D$3:$D$7),IF($A6=E$2,0,(XLOOKUP(SUBSTITUTE(E$2,"USD_",""),Daily_Rates!$A$3:$A$7,Daily_Rates!$E$3:$E$7)-XLOOKUP(SUBSTITUTE($A6,"USD_",""),Daily_Rates!$A$3:$A$7,Daily_Rates!$D$3:$D$7))/XLOOKUP(SUBSTITUTE($A6,"USD_",""),Daily_Rates!$A$3:$A$7,Daily_Rates!$D$3:$D$7))),"")} -> 0 | F6: {=iferror(IF(LEFT($A6,4)="AED_",(XLOOKUP(SUBSTITUTE(F$2,"USD_",""),Daily_Rates!$A$3:$A$7,Daily_Rates!$E$3:$E$7)-XLOOKUP(SUBSTITUTE(F$2,"USD_",""),Daily_Rates!$A$3:$A$7,Daily_Rates!$D$3:$D$7))/XLOOKUP(SUBSTITUTE(F$2,"USD_",""),Daily_Rates!$A$3:$A$7,Daily_Rates!$D$3:$D$7),IF($A6=F$2,0,(XLOOKUP(SUBSTITUTE(F$2,"USD_",""),Daily_Rates!$A$3:$A$7,Daily_Rates!$E$3:$E$7)-XLOOKUP(SUBSTITUTE($A6,"USD_",""),Daily_Rates!$A$3:$A$7,Daily_Rates!$D$3:$D$7))/XLOOKUP(SUBSTITUTE($A6,"USD_",""),Daily_Rates!$A$3:$A$7,Daily_Rates!$D$3:$D$7))),"")}
A7: AED_Dubai | B7: {=iferror(IF(LEFT($A7,4)="AED_",(XLOOKUP(SUBSTITUTE(B$2,"USD_",""),Daily_Rates!$A$3:$A$7,Daily_Rates!$E$3:$E$7)-XLOOKUP(SUBSTITUTE(B$2,"USD_",""),Daily_Rates!$A$3:$A$7,Daily_Rates!$D$3:$D$7))/XLOOKUP(SUBSTITUTE(B$2,"USD_",""),Daily_Rates!$A$3:$A$7,Daily_Rates!$D$3:$D$7),IF($A7=B$2,0,(XLOOKUP(SUBSTITUTE(B$2,"USD_",""),Daily_Rates!$A$3:$A$7,Daily_Rates!$E$3:$E$7)-XLOOKUP(SUBSTITUTE($A7,"USD_",""),Daily_Rates!$A$3:$A$7,Daily_Rates!$D$3:$D$7))/XLOOKUP(SUBSTITUTE($A7,"USD_",""),Daily_Rates!$A$3:$A$7,Daily_Rates!$D$3:$D$7))),"")} -> 0.0013642565 | C7: {=iferror(IF(LEFT($A7,4)="AED_",(XLOOKUP(SUBSTITUTE(C$2,"USD_",""),Daily_Rates!$A$3:$A$7,Daily_Rates!$E$3:$E$7)-XLOOKUP(SUBSTITUTE(C$2,"USD_",""),Daily_Rates!$A$3:$A$7,Daily_Rates!$D$3:$D$7))/XLOOKUP(SUBSTITUTE(C$2,"USD_",""),Daily_Rates!$A$3:$A$7,Daily_Rates!$D$3:$D$7),IF($A7=C$2,0,(XLOOKUP(SUBSTITUTE(C$2,"USD_",""),Daily_Rates!$A$3:$A$7,Daily_Rates!$E$3:$E$7)-XLOOKUP(SUBSTITUTE($A7,"USD_",""),Daily_Rates!$A$3:$A$7,Daily_Rates!$D$3:$D$7))/XLOOKUP(SUBSTITUTE($A7,"USD_",""),Daily_Rates!$A$3:$A$7,Daily_Rates!$D$3:$D$7))),"")} -> 0.002728513 | D7: {=iferror(IF(LEFT($A7,4)="AED_",(XLOOKUP(SUBSTITUTE(D$2,"USD_",""),Daily_Rates!$A$3:$A$7,Daily_Rates!$E$3:$E$7)-XLOOKUP(SUBSTITUTE(D$2,"USD_",""),Daily_Rates!$A$3:$A$7,Daily_Rates!$D$3:$D$7))/XLOOKUP(SUBSTITUTE(D$2,"USD_",""),Daily_Rates!$A$3:$A$7,Daily_Rates!$D$3:$D$7),IF($A7=D$2,0,(XLOOKUP(SUBSTITUTE(D$2,"USD_",""),Daily_Rates!$A$3:$A$7,Daily_Rates!$E$3:$E$7)-XLOOKUP(SUBSTITUTE($A7,"USD_",""),Daily_Rates!$A$3:$A$7,Daily_Rates!$D$3:$D$7))/XLOOKUP(SUBSTITUTE($A7,"USD_",""),Daily_Rates!$A$3:$A$7,Daily_Rates!$D$3:$D$7))),"")} -> 0.001630878 | E7: {=iferror(IF(LEFT($A7,4)="AED_",(XLOOKUP(SUBSTITUTE(E$2,"USD_",""),Daily_Rates!$A$3:$A$7,Daily_Rates!$E$3:$E$7)-XLOOKUP(SUBSTITUTE(E$2,"USD_",""),Daily_Rates!$A$3:$A$7,Daily_Rates!$D$3:$D$7))/XLOOKUP(SUBSTITUTE(E$2,"USD_",""),Daily_Rates!$A$3:$A$7,Daily_Rates!$D$3:$D$7),IF($A7=E$2,0,(XLOOKUP(SUBSTITUTE(E$2,"USD_",""),Daily_Rates!$A$3:$A$7,Daily_Rates!$E$3:$E$7)-XLOOKUP(SUBSTITUTE($A7,"USD_",""),Daily_Rates!$A$3:$A$7,Daily_Rates!$D$3:$D$7))/XLOOKUP(SUBSTITUTE($A7,"USD_",""),Daily_Rates!$A$3:$A$7,Daily_Rates!$D$3:$D$7))),"")} | F7: {=iferror(IF(LEFT($A7,4)="AED_",(XLOOKUP(SUBSTITUTE(F$2,"USD_",""),Daily_Rates!$A$3:$A$7,Daily_Rates!$E$3:$E$7)-XLOOKUP(SUBSTITUTE(F$2,"USD_",""),Daily_Rates!$A$3:$A$7,Daily_Rates!$D$3:$D$7))/XLOOKUP(SUBSTITUTE(F$2,"USD_",""),Daily_Rates!$A$3:$A$7,Daily_Rates!$D$3:$D$7),IF($A7=F$2,0,(XLOOKUP(SUBSTITUTE(F$2,"USD_",""),Daily_Rates!$A$3:$A$7,Daily_Rates!$E$3:$E$7)-XLOOKUP(SUBSTITUTE($A7,"USD_",""),Daily_Rates!$A$3:$A$7,Daily_Rates!$D$3:$D$7))/XLOOKUP(SUBSTITUTE($A7,"USD_",""),Daily_Rates!$A$3:$A$7,Daily_Rates!$D$3:$D$7))),"")}

Sheet Route_Comparison
A1: Route Comparison Engine (Percent-based)
A2: Route ID | B2: Route Name | C2: Active? | D2: Auto Conversion % | E2: Effective Conversion % | F2: Fee / Transfer % | G2: Total Cost % | H2: Cost Amount USD | I2: Action / Notes
A3: NO_FX | B3: اظهارنامه بدون ارز | C3: ="Yes" -> Yes | D3: {=INDEX(Conversion_Matrix!$B$3:$F$7,MATCH(Dashboard!$B$6,Conversion_Matrix!$A$3:$A$7,0),MATCH("USD_Tehran",Conversion_Matrix!$B$2:$F$2,0))} -> -0.001087252 | E3: =IF(Dashboard!$B$11="Yes",Dashboard!$B$12,D3) -> -0.001087252 | F3: =Dashboard!$B$7 -> 0.007 | G3: =IF(C3="Yes",E3+F3,"") -> 0.005912748 | H3: =IF(G3="","",Dashboard!$B$5*G3) -> 5912.748 | I3: Origin → USD_Tehran + No-FX declaration
A4: DUBAI_FX | B4: اظهارنامه با ارز از مسیر دوبی | C4: ="Yes" -> Yes | D4: {=INDEX(Conversion_Matrix!$B$3:$F$7,MATCH(Dashboard!$B$6,Conversion_Matrix!$A$3:$A$7,0),MATCH("USD_Dubai",Conversion_Matrix!$B$2:$F$2,0))} | E4: =IF(Dashboard!$B$13="Yes",Dashboard!$B$14,D4) | F4: =Dashboard!$B$8 -> 0.005 | G4: =IF(C4="Yes",E4+F4,"") -> 0.005 | H4: =IF(G4="","",Dashboard!$B$5*G4) -> 5000 | I4: Origin → USD_Dubai + Dubai transfer/import fee
A5: IST_DIRECT | B5: اظهارنامه با ارز مستقیم استانبول | C5: =IF(Dashboard!$B$6="USD_Istanbul","Yes","No") -> Yes | D5: =0 -> 0 | E5: =0 -> 0 | F5: =Dashboard!$B$9 -> 0.015 | G5: =IF(C5="Yes",F5,"") -> 0.015 | H5: =IF(G5="","",Dashboard!$B$5*G5) -> 15000 | I5: Only active when Origin = USD_Istanbul

Sheet Notes
A1: Model Purpose
A2: Origin Naming | B2: Use explicit origin codes such as USD_Istanbul, AED_Dubai, USD_Tehran.
A3: AED_Dubai Logic | B3: When origin is AED_Dubai, conversion to USD_Dubai is not zero; it uses Dubai USD buy/sell spread.
A4: No-FX Route | B4: Origin → USD_Tehran + No-FX declaration fee.
A5: Dubai FX Route | B5: Origin → USD_Dubai + Dubai transfer/import fee.
A6: Istanbul Direct Route | B6: Only active when Origin Currency = USD_Istanbul.
A7: Manual Overrides | B7: Manual conversion costs and fees must be entered as percentages, e.g. 0.70%.
A8: Conversion Formula for USD origins | B8: (Destination Sell - Origin Buy) / Origin Buy.
A9: Conversion Formula for AED_Dubai origin | B9: (Destination Sell - Destination Buy) / Destination Buy.
A10: Source | B10: Daily market rates are pasted into Daily_Rate_Input. Daily_Rates reads from that input automatically.
A12: Daily_Report | B12: Compares all origin currencies at once using current Daily_Rates and Fees_Settings. Use this for daily decision-making.
A13: History | B13: Blank tracking table for daily snapshots. Copy Daily_Report outputs as values after each daily rate update.
A14: Origin logic | B14: AED_Dubai is treated as dirham origin, so conversion to USD_Tehran or USD_Dubai uses the destination market spread, not zero.
... A17: Arbitrage chat output | B17: Use columns: Date | Market | Buy | Sell | Notes. Markets must be exactly: Tether, Tehran, Istanbul, Sulaymaniyah, Dubai.

Sheet Daily_Report
A1: Daily FX Declaration Decision Report
A2: Report Date | B2: =Daily_Rate_Input!$A$3 -> -180686 | D2: No-FX Fee | E2: =Fees_Settings!$E$3 -> 0.007 | G2: Istanbul Direct Fee | H2: =Fees_Settings!$E$5 -> 0.015
A3: Report Amount USD | B3: =Dashboard!$B$5 -> 1000000 | D3: Dubai Transfer Fee | E3: =Fees_Settings!$E$4 -> 0.005 | G3: Source | H3: Daily_Rate_Input + Daily_Rates + Fees_Settings
A5: Origin Code | B5: Origin Label | C5: No-FX Conv % | D5: No-FX Fee % | E5: No-FX Total % | F5: Dubai Conv % | G5: Dubai Transfer % | H5: Dubai Total % | I5: Istanbul Direct % | J5: Best Route | K5: Best Cost % | L5: Second Best % | M5: Saving vs Next % | N5: Cost Amount USD | O5: Decision Explanation | P5: Next Action | Q5: Report Line
A6: USD_Tehran | B6: دلار تهران | C6: {=INDEX(Conversion_Matrix!$B$3:$F$7,MATCH($A6,Conversion_Matrix!$A$3:$A$7,0),MATCH("USD_Tehran",Conversion_Matrix!$B$2:$F$2,0))} -> 0 | D6: =Fees_Settings!$E$3 -> 0.007 | E6: =C6+D6 -> 0.007 | F6: {=INDEX(Conversion_Matrix!$B$3:$F$7,MATCH($A6,Conversion_Matrix!$A$3:$A$7,0),MATCH("USD_Dubai",Conversion_Matrix!$B$2:$F$2,0))} | G6: =Fees_Settings!$E$4 -> 0.005 | H6: =F6+G6 -> 0.005 | I6: =IF($A6="USD_Istanbul",Fees_Settings!$E$5,"") | J6: =IF(MIN($E6,$H6,IF($I6="",9^9,$I6))=$E6,"اظهارنامه بدون ارز",IF(MIN($E6,$H6,IF($I6="",9^9,$I6))=$H6,"اظهارنامه با ارز از مسیر دوبی","اظهارنامه با ارز مستقیم استانبول")) -> اظهارنامه با ارز از مسیر دوبی | K6: =MIN($E6,$H6,IF($I6="",9^9,$I6)) -> 0.005 | L6: =IF($I6="",MAX($E6,$H6),MIN(MAX($E6,$H6),MAX($E6,$I6),MAX($H6,$I6))) -> 0.007 | M6: =L6-K6 -> 0.002 | N6: =$B$3*K6 -> 5000 | O6: =IFERROR(__xludf.DUMMYFUNCTION("LET( routes,{""اظهارنامه بدون ارز"",E6;""اظهارنامه با ارز از مسیر دوبی"",H6;""اظهارنامه با ارز مستقیم استانبول"",I6}, nextRoutes,SORT(FILTER(routes,INDEX(routes,,1)<>J6,INDEX(routes,,2)>0),2,TRUE), ""بهترین مسیر امروز برای رفع تعهد با منشأ ارز ""&B6&""، «"&"""&J6&""» است.""&CHAR(10)& ""هزینه تمام‌شده این مسیر ""&TEXT(K6,""0.00%"")&"" معادل حدود ""&TEXT(N6,""#,##0"")&"" دلار است.""&CHAR(10)&CHAR(10)& IF(J6=""اظهارنامه بدون ارز"", ""مشتری ""&TEXT(D6,""0.00%"")&"" هزینه کارمزد اظهارنامه بدون ارز پرداخت می‌کند و"&" ""&IF(C6<0,TEXT(ABS(C6),""0.00%"")&"" بابت تبدیل ""&B6&"" به دلار تهران سر می‌گیرد"",TEXT(C6,""0.00%"")&"" بابت تبدیل ""&B6&"" به دلار تهران هزینه می‌دهد"")&""؛ بنابراین هزینه نهایی ""&TEXT(E6,""0.00%"")&"" می‌شود."", IF(J6=""اظهارنامه با ارز از مسیر دوب"&"ی"", ""مشتری ""&IF(F6<0,TEXT(ABS(F6),""0.00%"")&"" بابت تبدیل ""&B6&"" به دلار دوبی سر می‌گیرد"",TEXT(F6,""0.00%"")&"" بابت تبدیل ""&B6&"" به دلار دوبی هزینه می‌دهد"")&"" و ""&TEXT(G6,""0.00%"")&"" هزینه انتقال / ورود ارز از مسیر دوبی پرداخت می‌کند؛ بنابر"&"این هزینه نهایی ""&TEXT(H6,""0.00%"")&"" می‌شود."", ""مشتری از مسیر مستقیم استانبول استفاده می‌کند. این مسیر شامل تبدیل ارز و هزینه انتقال است و کارمزد ثابت آن ""&TEXT(I6,""0.00%"")&"" است."" ))&CHAR(10)&CHAR(10)& ""گزینه‌های بعدی به ترتیب هزینه:""&CHAR(1"&"0)& TEXTJOIN(CHAR(10),TRUE,ARRAYFORMULA(""- ""&INDEX(nextRoutes,,1)&"": هزینه تمام‌شده ""&TEXT(INDEX(nextRoutes,,2),""0.00%"")&"" معادل حدود ""&TEXT($B$3*INDEX(nextRoutes,,2),""#,##0"")&"" دلار.""))&CHAR(10)&CHAR(10)& ""اختلاف بهترین مسیر با نزدیک‌ترین گز"&"ینه بعدی ""&TEXT(M6,""0.00%"")&"" معادل حدود ""&TEXT($B$3*M6,""#,##0"")&"" دلار است."" )"),"بهترین مسیر امروز برای رفع تعهد با منشأ ارز دلار تهران، «اظهارنامه با ارز از مسیر دوبی» است. هزینه تمام‌شده این مسیر 0.50% معادل حدود 5,000 دلار است. مشتری بابت تبدیل دلار تهران به دلار دوبی هزینه می‌دهد و 0.50% هزینه انتقال / ورود ارز از مسیر دوبی پردا"&"خت می‌کند؛ بنابراین هزینه نهایی 0.50% می‌شود. گزینه‌های بعدی به ترتیب هزینه: - اظهارنامه بدون ارز: هزینه تمام‌شده 0.70% معادل حدود 7,000 دلار. - اظهارنامه با ارز مستقیم استانبول: هزینه تمام‌شده معادل حدود 0 دلار. اختلاف بهترین مسیر با نزدیک‌ترین گزینه "&"بعدی 0.20% معادل حدود 2,000 دلار است.") -> بهترین مسیر امروز برای رفع تعهد با منشأ ارز دلار تهران، «اظهارنامه با ارز از مسیر دوبی» است. هزینه تمام‌شده این مسیر 0.50% معادل حدود 5,000 دلار است. مشتری بابت تبدیل دلار تهران به دلار دوبی هزینه می‌دهد و 0.50% هزینه انتقال / ورود ارز از مسیر دوبی پرداخت می‌کند؛ بنابراین هزینه نهایی 0.50% می‌شود. گزینه‌های بعدی به ترتیب هزینه: - اظهارنامه بدون ارز: هزینه تمام‌شده 0.70% معادل حدود 7,000 دلار. - اظهارنامه با ارز مستقیم استانبول: هزینه تمام‌شده معادل حدود 0 دلار. اختلاف بهترین مسیر با نزدیک‌ترین گزینه بعدی 0.20% معادل حدود 2,000 دلار است. | P6: =IF(J6="اظهارنامه بدون ارز","اقدام: خرید/تأمین اظهارنامه بدون ارز و تبدیل منشأ به دلار تهران.",IF(J6="اظهارنامه با ارز از مسیر دوبی","اقدام: تبدیل منشأ به دلار دوبی، ثبت اردر اظهارنامه با ارز از مسیر دوبی و هماهنگی ورود ارز.","اقدام: هماهنگی با تأمین‌کننده مستقیم استانبول و دریافت تأیید کارمزد ثابت.")) -> اقدام: تبدیل منشأ به دلار دوبی، ثبت اردر اظهارنامه با ارز از مسیر دوبی و هماهنگی ورود ارز. | Q6: ="- "&B6&": "&J6&" | هزینه "&TEXT(K6,"0.00%")&" | صرفه نسبت به گزینه بعدی "&TEXT(M6,"0.00%") -> - دلار تهران: اظهارنامه با ارز از مسیر دوبی | هزینه 0.50% | صرفه نسبت به گزینه بعدی 0.20%
A7: USD_Istanbul | B7: دلار استانبول | C7: {=INDEX(Conversion_Matrix!$B$3:$F$7,MATCH($A7,Conversion_Matrix!$A$3:$A$7,0),MATCH("USD_Tehran",Conversion_Matrix!$B$2:$F$2,0))} -> -0.001087252 | D7: =Fees_Settings!$E$3 -> 0.007 | E7: =C7+D7 -> 0.005912748 | F7: {=INDEX(Conversion_Matrix!$B$3:$F$7,MATCH($A7,Conversion_Matrix!$A$3:$A$7,0),MATCH("USD_Dubai",Conversion_Matrix!$B$2:$F$2,0))} | G7: =Fees_Settings!$E$4 -> 0.005 | H7: =F7+G7 -> 0.005 | I7: =IF($A7="USD_Istanbul",Fees_Settings!$E$5,"") -> 0.015 | J7: =IF(MIN($E7,$H7,IF($I7="",9^9,$I7))=$E7,"اظهارنامه بدون ارز",IF(MIN($E7,$H7,IF($I7="",9^9,$I7))=$H7,"اظهارنامه با ارز از مسیر دوبی","اظهارنامه با ارز مستقیم استانبول")) -> اظهارنامه با ارز از مسیر دوبی | K7: =MIN($E7,$H7,IF($I7="",9^9,$I7)) -> 0.005 | L7: =IF($I7="",MAX($E7,$H7),MIN(MAX($E7,$H7),MAX($E7,$I7),MAX($H7,$I7))) -> 0.005912748 | M7: =L7-K7 -> 0.00091274803 | N7: =$B$3*K7 -> 5000 | O7: =IFERROR(__xludf.DUMMYFUNCTION("LET( routes,{""اظهارنامه بدون ارز"",E7;""اظهارنامه با ارز از مسیر دوبی"",H7;""اظهارنامه با ارز مستقیم استانبول"",I7}, nextRoutes,SORT(FILTER(routes,INDEX(routes,,1)<>J7,INDEX(routes,,2)>0),2,TRUE), ""بهترین مسیر امروز برای رفع تعهد با منشأ ارز ""&B7&""، «"&"""&J7&""» است.""&CHAR(10)& ""هزینه تمام‌شده این مسیر ""&TEXT(K7,""0.00%"")&"" معادل حدود ""&TEXT(N7,""#,##0"")&"" دلار است.""&CHAR(10)&CHAR(10)& IF(J7=""اظهارنامه بدون ارز"", ""مشتری ""&TEXT(D7,""0.00%"")&"" هزینه کارمزد اظهارنامه بدون ارز پرداخت می‌کند و"&" ""&IF(C7<0,TEXT(ABS(C7),""0.00%"")&"" بابت تبدیل ""&B7&"" به دلار تهران سر می‌گیرد"",TEXT(C7,""0.00%"")&"" بابت تبدیل ""&B7&"" به دلار تهران هزینه می‌دهد"")&""؛ بنابراین هزینه نهایی ""&TEXT(E7,""0.00%"")&"" می‌شود."", IF(J7=""اظهارنامه با ارز از مسیر دوب"&"ی"", ""مشتری ""&IF(F7<0,TEXT(ABS(F7),""0.00%"")&"" بابت تبدیل ""&B7&"" به دلار دوبی سر می‌گیرد"",TEXT(F7,""0.00%"")&"" بابت تبدیل ""&B7&"" به دلار دوبی هزینه می‌دهد"")&"" و ""&TEXT(G7,""0.00%"")&"" هزینه انتقال / ورود ارز از مسیر دوبی پرداخت می‌کند؛ بنابر"&"این هزینه نهایی ""&TEXT(H7,""0.00%"")&"" می‌شود."", ""مشتری از مسیر مستقیم استانبول استفاده می‌کند. این مسیر شامل تبدیل ارز و هزینه انتقال است و کارمزد ثابت آن ""&TEXT(I7,""0.00%"")&"" است."" ))&CHAR(10)&CHAR(10)& ""گزینه‌های بعدی به ترتیب هزینه:""&CHAR(1"&"0)& TEXTJOIN(CHAR(10),TRUE,ARRAYFORMULA(""- ""&INDEX(nextRoutes,,1)&"": هزینه تمام‌شده ""&TEXT(INDEX(nextRoutes,,2),""0.00%"")&"" معادل حدود ""&TEXT($B$3*INDEX(nextRoutes,,2),""#,##0"")&"" دلار.""))&CHAR(10)&CHAR(10)& ""اختلاف بهترین مسیر با نزدیک‌ترین گز"&"ینه بعدی ""&TEXT(M7,""0.00%"")&"" معادل حدود ""&TEXT($B$3*M7,""#,##0"")&"" دلار است."" )"),"بهترین مسیر امروز برای رفع تعهد با منشأ ارز دلار استانبول، «اظهارنامه با ارز از مسیر دوبی» است. هزینه تمام‌شده این مسیر 0.50% معادل حدود 5,000 دلار است. مشتری بابت تبدیل دلار استانبول به دلار دوبی هزینه می‌دهد و 0.50% هزینه انتقال / ورود ارز از مسیر دوب"&"ی پرداخت می‌کند؛ بنابراین هزینه نهایی 0.50% می‌شود. گزینه‌های بعدی به ترتیب هزینه: - اظهارنامه بدون ارز: هزینه تمام‌شده 0.59% معادل حدود 5,913 دلار. - اظهارنامه با ارز مستقیم استانبول: هزینه تمام‌شده 1.50% معادل حدود 15,000 دلار. اختلاف بهترین مسیر با ن"&"زدیک‌ترین گزینه بعدی 0.09% معادل حدود 913 دلار است.") -> بهترین مسیر امروز برای رفع تعهد با منشأ ارز دلار استانبول، «اظهارنامه با ارز از مسیر دوبی» است. هزینه تمام‌شده این مسیر 0.50% معادل حدود 5,000 دلار است. مشتری بابت تبدیل دلار استانبول به دلار دوبی هزینه می‌دهد و 0.50% هزینه انتقال / ورود ارز از مسیر دوبی پرداخت می‌کند؛ بنابراین هزینه نهایی 0.50% می‌شود. گزینه‌های بعدی به ترتیب هزینه: - اظهارنامه بدون ارز: هزینه تمام‌شده 0.59% معادل حدود 5,913 دلار. - اظهارنامه با ارز مستقیم استانبول: هزینه تمام‌شده 1.50% معادل حدود 15,000 دلار. اختلاف بهترین مسیر با نزدیک‌ترین گزینه بعدی 0.09% معادل حدود 913 دلار است. | P7: =IF(J7="اظهارنامه بدون ارز","اقدام: خرید/تأمین اظهارنامه بدون ارز و تبدیل منشأ به دلار تهران.",IF(J7="اظهارنامه با ارز از مسیر دوبی","اقدام: تبدیل منشأ به دلار دوبی، ثبت اردر اظهارنامه با ارز از مسیر دوبی و هماهنگی ورود ارز.","اقدام: هماهنگی با تأمین‌کننده مستقیم استانبول و دریافت تأیید کارمزد ثابت.")) -> اقدام: تبدیل منشأ به دلار دوبی، ثبت اردر اظهارنامه با ارز از مسیر دوبی و هماهنگی ورود ارز. | Q7: ="- "&B7&": "&J7&" | هزینه "&TEXT(K7,"0.00%")&" | صرفه نسبت به گزینه بعدی "&TEXT(M7,"0.00%") -> - دلار استانبول: اظهارنامه با ارز از مسیر دوبی | هزینه 0.50% | صرفه نسبت به گزینه بعدی 0.09%
A8: USD_Sulaymaniyah | B8: دلار سلیمانیه | C8: {=INDEX(Conversion_Matrix!$B$3:$F$7,MATCH($A8,Conversion_Matrix!$A$3:$A$7,0),MATCH("USD_Tehran",Conversion_Matrix!$B$2:$F$2,0))} | D8: =Fees_Settings!$E$3 -> 0.007 | E8: =C8+D8 -> 0.007 | F8: {=INDEX(Conversion_Matrix!$B$3:$F$7,MATCH($A8,Conversion_Matrix!$A$3:$A$7,0),MATCH("USD_Dubai",Conversion_Matrix!$B$2:$F$2,0))} | G8: =Fees_Settings!$E$4 -> 0.005 | H8: =F8+G8 -> 0.005 | I8: =IF($A8="USD_Istanbul",Fees_Settings!$E$5,"") | J8: =IF(MIN($E8,$H8,IF($I8="",9^9,$I8))=$E8,"اظهارنامه بدون ارز",IF(MIN($E8,$H8,IF($I8="",9^9,$I8))=$H8,"اظهارنامه با ارز از مسیر دوبی","اظهارنامه با ارز مستقیم استانبول")) -> اظهارنامه با ارز از مسیر دوبی | K8: =MIN($E8,$H8,IF($I8="",9^9,$I8)) -> 0.005 | L8: =IF($I8="",MAX($E8,$H8),MIN(MAX($E8,$H8),MAX($E8,$I8),MAX($H8,$I8))) -> 0.007 | M8: =L8-K8 -> 0.002 | N8: =$B$3*K8 -> 5000 | O8: =IFERROR(__xludf.DUMMYFUNCTION("LET( routes,{""اظهارنامه بدون ارز"",E8;""اظهارنامه با ارز از مسیر دوبی"",H8;""اظهارنامه با ارز مستقیم استانبول"",I8}, nextRoutes,SORT(FILTER(routes,INDEX(routes,,1)<>J8,INDEX(routes,,2)>0),2,TRUE), ""بهترین مسیر امروز برای رفع تعهد با منشأ ارز ""&B8&""، «"&"""&J8&""» است.""&CHAR(10)& ""هزینه تمام‌شده این مسیر ""&TEXT(K8,""0.00%"")&"" معادل حدود ""&TEXT(N8,""#,##0"")&"" دلار است.""&CHAR(10)&CHAR(10)& IF(J8=""اظهارنامه بدون ارز"", ""مشتری ""&TEXT(D8,""0.00%"")&"" هزینه کارمزد اظهارنامه بدون ارز پرداخت می‌کند و"&" ""&IF(C8<0,TEXT(ABS(C8),""0.00%"")&"" بابت تبدیل ""&B8&"" به دلار تهران سر می‌گیرد"",TEXT(C8,""0.00%"")&"" بابت تبدیل ""&B8&"" به دلار تهران هزینه می‌دهد"")&""؛ بنابراین هزینه نهایی ""&TEXT(E8,""0.00%"")&"" می‌شود."", IF(J8=""اظهارنامه با ارز از مسیر دوب"&"ی"", ""مشتری ""&IF(F8<0,TEXT(ABS(F8),""0.00%"")&"" بابت تبدیل ""&B8&"" به دلار دوبی سر می‌گیرد"",TEXT(F8,""0.00%"")&"" بابت تبدیل ""&B8&"" به دلار دوبی هزینه می‌دهد"")&"" و ""&TEXT(G8,""0.00%"")&"" هزینه انتقال / ورود ارز از مسیر دوبی پرداخت می‌کند؛ بنابر"&"این هزینه نهایی ""&TEXT(H8,""0.00%"")&"" می‌شود."", ""مشتری از مسیر مستقیم استانبول استفاده می‌کند. این مسیر شامل تبدیل ارز و هزینه انتقال است و کارمزد ثابت آن ""&TEXT(I8,""0.00%"")&"" است."" ))&CHAR(10)&CHAR(10)& ""گزینه‌های بعدی به ترتیب هزینه:""&CHAR(1"&"0)& TEXTJOIN(CHAR(10),TRUE,ARRAYFORMULA(""- ""&INDEX(nextRoutes,,1)&"": هزینه تمام‌شده ""&TEXT(INDEX(nextRoutes,,2),""0.00%"")&"" معادل حدود ""&TEXT($B$3*INDEX(nextRoutes,,2),""#,##0"")&"" دلار.""))&CHAR(10)&CHAR(10)& ""اختلاف بهترین مسیر با نزدیک‌ترین گز"&"ینه بعدی ""&TEXT(M8,""0.00%"")&"" معادل حدود ""&TEXT($B$3*M8,""#,##0"")&"" دلار است."" )"),"بهترین مسیر امروز برای رفع تعهد با منشأ ارز دلار سلیمانیه، «اظهارنامه با ارز از مسیر دوبی» است. هزینه تمام‌شده این مسیر 0.50% معادل حدود 5,000 دلار است. مشتری بابت تبدیل دلار سلیمانیه به دلار دوبی هزینه می‌دهد و 0.50% هزینه انتقال / ورود ارز از مسیر دوب"&"ی پرداخت می‌کند؛ بنابراین هزینه نهایی 0.50% می‌شود. گزینه‌های بعدی به ترتیب هزینه: - اظهارنامه بدون ارز: هزینه تمام‌شده 0.70% معادل حدود 7,000 دلار. - اظهارنامه با ارز مستقیم استانبول: هزینه تمام‌شده معادل حدود 0 دلار. اختلاف بهترین مسیر با نزدیک‌ترین "&"گزینه بعدی 0.20% معادل حدود 2,000 دلار است.") -> بهترین مسیر امروز برای رفع تعهد با منشأ ارز دلار سلیمانیه، «اظهارنامه با ارز از مسیر دوبی» است. هزینه تمام‌شده این مسیر 0.50% معادل حدود 5,000 دلار است. مشتری بابت تبدیل دلار سلیمانیه به دلار دوبی هزینه می‌دهد و 0.50% هزینه انتقال / ورود ارز از مسیر دوبی پرداخت می‌کند؛ بنابراین هزینه نهایی 0.50% می‌شود. گزینه‌های بعدی به ترتیب هزینه: - اظهارنامه بدون ارز: هزینه تمام‌شده 0.70% معادل حدود 7,000 دلار. - اظهارنامه با ارز مستقیم استانبول: هزینه تمام‌شده معادل حدود 0 دلار. اختلاف بهترین مسیر با نزدیک‌ترین گزینه بعدی 0.20% معادل حدود 2,000 دلار است. | P8: =IF(J8="اظهارنامه بدون ارز","اقدام: خرید/تأمین اظهارنامه بدون ارز و تبدیل منشأ به دلار تهران.",IF(J8="اظهارنامه با ارز از مسیر دوبی","اقدام: تبدیل منشأ به دلار دوبی، ثبت اردر اظهارنامه با ارز از مسیر دوبی و هماهنگی ورود ارز.","اقدام: هماهنگی با تأمین‌کننده مستقیم استانبول و دریافت تأیید کارمزد ثابت.")) -> اقدام: تبدیل منشأ به دلار دوبی، ثبت اردر اظهارنامه با ارز از مسیر دوبی و هماهنگی ورود ارز. | Q8: ="- "&B8&": "&J8&" | هزینه "&TEXT(K8,"0.00%")&" | صرفه نسبت به گزینه بعدی "&TEXT(M8,"0.00%") -> - دلار سلیمانیه: اظهارنامه با ارز از مسیر دوبی | هزینه 0.50% | صرفه نسبت به گزینه بعدی 0.20%
A9: USD_Tether | B9: دلار تتر | C9: {=INDEX(Conversion_Matrix!$B$3:$F$7,MATCH($A9,Conversion_Matrix!$A$3:$A$7,0),MATCH("USD_Tehran",Conversion_Matrix!$B$2:$F$2,0))} -> 0.002728513 | D9: =Fees_Settings!$E$3 -> 0.007 | E9: =C9+D9 -> 0.009728513 | F9: {=INDEX(Conversion_Matrix!$B$3:$F$7,MATCH($A9,Conversion_Matrix!$A$3:$A$7,0),MATCH("USD_Dubai",Conversion_Matrix!$B$2:$F$2,0))} | G9: =Fees_Settings!$E$4 -> 0.005 | H9: =F9+G9 -> 0.005 | I9: =IF($A9="USD_Istanbul",Fees_Settings!$E$5,"") | J9: =IF(MIN($E9,$H9,IF($I9="",9^9,$I9))=$E9,"اظهارنامه بدون ارز",IF(MIN($E9,$H9,IF($I9="",9^9,$I9))=$H9,"اظهارنامه با ارز از مسیر دوبی","اظهارنامه با ارز مستقیم استانبول")) -> اظهارنامه با ارز از مسیر دوبی | K9: =MIN($E9,$H9,IF($I9="",9^9,$I9)) -> 0.005 | L9: =IF($I9="",MAX($E9,$H9),MIN(MAX($E9,$H9),MAX($E9,$I9),MAX($H9,$I9))) -> 0.009728513 | M9: =L9-K9 -> 0.004728513 | N9: =$B$3*K9 -> 5000 | O9: =IFERROR(__xludf.DUMMYFUNCTION("LET( routes,{""اظهارنامه بدون ارز"",E9;""اظهارنامه با ارز از مسیر دوبی"",H9;""اظهارنامه با ارز مستقیم استانبول"",I9}, nextRoutes,SORT(FILTER(routes,INDEX(routes,,1)<>J9,INDEX(routes,,2)>0),2,TRUE), ""بهترین مسیر امروز برای رفع تعهد با منشأ ارز ""&B9&""، «"&"""&J9&""» است.""&CHAR(10)& ""هزینه تمام‌شده این مسیر ""&TEXT(K9,""0.00%"")&"" معادل حدود ""&TEXT(N9,""#,##0"")&"" دلار است.""&CHAR(10)&CHAR(10)& IF(J9=""اظهارنامه بدون ارز"", ""مشتری ""&TEXT(D9,""0.00%"")&"" هزینه کارمزد اظهارنامه بدون ارز پرداخت می‌کند و"&" ""&IF(C9<0,TEXT(ABS(C9),""0.00%"")&"" بابت تبدیل ""&B9&"" به دلار تهران سر می‌گیرد"",TEXT(C9,""0.00%"")&"" بابت تبدیل ""&B9&"" به دلار تهران هزینه می‌دهد"")&""؛ بنابراین هزینه نهایی ""&TEXT(E9,""0.00%"")&"" می‌شود."", IF(J9=""اظهارنامه با ارز از مسیر دوب"&"ی"", ""مشتری ""&IF(F9<0,TEXT(ABS(F9),""0.00%"")&"" بابت تبدیل ""&B9&"" به دلار دوبی سر می‌گیرد"",TEXT(F9,""0.00%"")&"" بابت تبدیل ""&B9&"" به دلار دوبی هزینه می‌دهد"")&"" و ""&TEXT(G9,""0.00%"")&"" هزینه انتقال / ورود ارز از مسیر دوبی پرداخت می‌کند؛ بنابر"&"این هزینه نهایی ""&TEXT(H9,""0.00%"")&"" می‌شود."", ""مشتری از مسیر مستقیم استانبول استفاده می‌کند. این مسیر شامل تبدیل ارز و هزینه انتقال است و کارمزد ثابت آن ""&TEXT(I9,""0.00%"")&"" است."" ))&CHAR(10)&CHAR(10)& ""گزینه‌های بعدی به ترتیب هزینه:""&CHAR(1"&"0)& TEXTJOIN(CHAR(10),TRUE,ARRAYFORMULA(""- ""&INDEX(nextRoutes,,1)&"": هزینه تمام‌شده ""&TEXT(INDEX(nextRoutes,,2),""0.00%"")&"" معادل حدود ""&TEXT($B$3*INDEX(nextRoutes,,2),""#,##0"")&"" دلار.""))&CHAR(10)&CHAR(10)& ""اختلاف بهترین مسیر با نزدیک‌ترین گز"&"ینه بعدی ""&TEXT(M9,""0.00%"")&"" معادل حدود ""&TEXT($B$3*M9,""#,##0"")&"" دلار است."" )"),"بهترین مسیر امروز برای رفع تعهد با منشأ ارز دلار تتر، «اظهارنامه با ارز از مسیر دوبی» است. هزینه تمام‌شده این مسیر 0.50% معادل حدود 5,000 دلار است. مشتری بابت تبدیل دلار تتر به دلار دوبی هزینه می‌دهد و 0.50% هزینه انتقال / ورود ارز از مسیر دوبی پرداخت م"&"ی‌کند؛ بنابراین هزینه نهایی 0.50% می‌شود. گزینه‌های بعدی به ترتیب هزینه: - اظهارنامه بدون ارز: هزینه تمام‌شده 0.97% معادل حدود 9,729 دلار. - اظهارنامه با ارز مستقیم استانبول: هزینه تمام‌شده معادل حدود 0 دلار. اختلاف بهترین مسیر با نزدیک‌ترین گزینه بعدی"&" 0.47% معادل حدود 4,729 دلار است.") -> بهترین مسیر امروز برای رفع تعهد با منشأ ارز دلار تتر، «اظهارنامه با ارز از مسیر دوبی» است. هزینه تمام‌شده این مسیر 0.50% معادل حدود 5,000 دلار است. مشتری بابت تبدیل دلار تتر به دلار دوبی هزینه می‌دهد و 0.50% هزینه انتقال / ورود ارز از مسیر دوبی پرداخت می‌کند؛ بنابراین هزینه نهایی 0.50% می‌شود. گزینه‌های بعدی به ترتیب هزینه: - اظهارنامه بدون ارز: هزینه تمام‌شده 0.97% معادل حدود 9,729 دلار. - اظهارنامه با ارز مستقیم استانبول: هزینه تمام‌شده معادل حدود 0 دلار. اختلاف بهترین مسیر با نزدیک‌ترین گزینه بعدی 0.47% معادل حدود 4,729 دلار است. | P9: =IF(J9="اظهارنامه بدون ارز","اقدام: خرید/تأمین اظهارنامه بدون ارز و تبدیل منشأ به دلار تهران.",IF(J9="اظهارنامه با ارز از مسیر دوبی","اقدام: تبدیل منشأ به دلار دوبی، ثبت اردر اظهارنامه با ارز از مسیر دوبی و هماهنگی ورود ارز.","اقدام: هماهنگی با تأمین‌کننده مستقیم استانبول و دریافت تأیید کارمزد ثابت.")) -> اقدام: تبدیل منشأ به دلار دوبی، ثبت اردر اظهارنامه با ارز از مسیر دوبی و هماهنگی ورود ارز. | Q9: ="- "&B9&": "&J9&" | هزینه "&TEXT(K9,"0.00%")&" | صرفه نسبت به گزینه بعدی "&TEXT(M9,"0.00%") -> - دلار تتر: اظهارنامه با ارز از مسیر دوبی | هزینه 0.50% | صرفه نسبت به گزینه بعدی 0.47%
A10: AED_Dubai | B10: درهم دوبی | C10: {=INDEX(Conversion_Matrix!$B$3:$F$7,MATCH($A10,Conversion_Matrix!$A$3:$A$7,0),MATCH("USD_Tehran",Conversion_Matrix!$B$2:$F$2,0))} -> 0.002728513 | D10: =Fees_Settings!$E$3 -> 0.007 | E10: =C10+D10 -> 0.009728513 | F10: {=INDEX(Conversion_Matrix!$B$3:$F$7,MATCH($A10,Conversion_Matrix!$A$3:$A$7,0),MATCH("USD_Dubai",Conversion_Matrix!$B$2:$F$2,0))} | G10: =Fees_Settings!$E$4 -> 0.005 | H10: =F10+G10 -> 0.005 | I10: =IF($A10="USD_Istanbul",Fees_Settings!$E$5,"") | J10: =IF(MIN($E10,$H10,IF($I10="",9^9,$I10))=$E10,"اظهارنامه بدون ارز",IF(MIN($E10,$H10,IF($I10="",9^9,$I10))=$H10,"اظهارنامه با ارز از مسیر دوبی","اظهارنامه با ارز مستقیم استانبول")) -> اظهارنامه با ارز از مسیر دوبی | K10: =MIN($E10,$H10,IF($I10="",9^9,$I10)) -> 0.005 | L10: =IF($I10="",MAX($E10,$H10),MIN(MAX($E10,$H10),MAX($E10,$I10),MAX($H10,$I10))) -> 0.009728513 | M10: =L10-K10 -> 0.004728513 | N10: =$B$3*K10 -> 5000 | O10: =IFERROR(__xludf.DUMMYFUNCTION("LET( routes,{""اظهارنامه بدون ارز"",E10;""اظهارنامه با ارز از مسیر دوبی"",H10;""اظهارنامه با ارز مستقیم استانبول"",I10}, nextRoutes,SORT(FILTER(routes,INDEX(routes,,1)<>J10,INDEX(routes,,2)>0),2,TRUE), ""بهترین مسیر امروز برای رفع تعهد با منشأ ارز ""&B10&"&"""، «""&J10&""» است.""&CHAR(10)& ""هزینه تمام‌شده این مسیر ""&TEXT(K10,""0.00%"")&"" معادل حدود ""&TEXT(N10,""#,##0"")&"" دلار است.""&CHAR(10)&CHAR(10)& IF(J10=""اظهارنامه بدون ارز"", ""مشتری ""&TEXT(D10,""0.00%"")&"" هزینه کارمزد اظهارنامه بدون ارز پرداخ"&"ت می‌کند و ""&IF(C10<0,TEXT(ABS(C10),""0.00%"")&"" بابت تبدیل ""&B10&"" به دلار تهران سر می‌گیرد"",TEXT(C10,""0.00%"")&"" بابت تبدیل ""&B10&"" به دلار تهران هزینه می‌دهد"")&""؛ بنابراین هزینه نهایی ""&TEXT(E10,""0.00%"")&"" می‌شود."", IF(J10=""اظهارنامه ب"&"ا ارز از مسیر دوبی"", ""مشتری ""&IF(F10<0,TEXT(ABS(F10),""0.00%"")&"" بابت تبدیل ""&B10&"" به دلار دوبی سر می‌گیرد"",TEXT(F10,""0.00%"")&"" بابت تبدیل ""&B10&"" به دلار دوبی هزینه می‌دهد"")&"" و ""&TEXT(G10,""0.00%"")&"" هزینه انتقال / ورود ارز از مسیر دو"&"بی پرداخت می‌کند؛ بنابراین هزینه نهایی ""&TEXT(H10,""0.00%"")&"" می‌شود."", ""مشتری از مسیر مستقیم استانبول استفاده می‌کند. این مسیر شامل تبدیل ارز و هزینه انتقال است و کارمزد ثابت آن ""&TEXT(I10,""0.00%"")&"" است."" ))&CHAR(10)&CHAR(10)& ""گزینه‌های بعدی"&" به ترتیب هزینه:""&CHAR(10)& TEXTJOIN(CHAR(10),TRUE,ARRAYFORMULA(""- ""&INDEX(nextRoutes,,1)&"": هزینه تمام‌شده ""&TEXT(INDEX(nextRoutes,,2),""0.00%"")&"" معادل حدود ""&TEXT($B$3*INDEX(nextRoutes,,2),""#,##0"")&"" دلار.""))&CHAR(10)&CHAR(10)& ""اختلاف بهت"&"رین مسیر با نزدیک‌ترین گزینه بعدی ""&TEXT(M10,""0.00%"")&"" معادل حدود ""&TEXT($B$3*M10,""#,##0"")&"" دلار است."" )"),"بهترین مسیر امروز برای رفع تعهد با منشأ ارز درهم دوبی، «اظهارنامه با ارز از مسیر دوبی» است. هزینه تمام‌شده این مسیر 0.50% معادل حدود 5,000 دلار است. مشتری بابت تبدیل درهم دوبی به دلار دوبی هزینه می‌دهد و 0.50% هزینه انتقال / ورود ارز از مسیر دوبی پرداخت"&" می‌کند؛ بنابراین هزینه نهایی 0.50% می‌شود. گزینه‌های بعدی به ترتیب هزینه: - اظهارنامه بدون ارز: هزینه تمام‌شده 0.97% معادل حدود 9,729 دلار. - اظهارنامه با ارز مستقیم استانبول: هزینه تمام‌شده معادل حدود 0 دلار. اختلاف بهترین مسیر با نزدیک‌ترین گزینه بع"&"دی 0.47% معادل حدود 4,729 دلار است.") -> بهترین مسیر امروز برای رفع تعهد با منشأ ارز درهم دوبی، «اظهارنامه با ارز از مسیر دوبی» است. هزینه تمام‌شده این مسیر 0.50% معادل حدود 5,000 دلار است. مشتری بابت تبدیل درهم دوبی به دلار دوبی هزینه می‌دهد و 0.50% هزینه انتقال / ورود ارز از مسیر دوبی پرداخت می‌کند؛ بنابراین هزینه نهایی 0.50% می‌شود. گزینه‌های بعدی به ترتیب هزینه: - اظهارنامه بدون ارز: هزینه تمام‌شده 0.97% معادل حدود 9,729 دلار. - اظهارنامه با ارز مستقیم استانبول: هزینه تمام‌شده معادل حدود 0 دلار. اختلاف بهترین مسیر با نزدیک‌ترین گزینه بعدی 0.47% معادل حدود 4,729 دلار است. | P10: =IF(J10="اظهارنامه بدون ارز","اقدام: خرید/تأمین اظهارنامه بدون ارز و تبدیل منشأ به دلار تهران.",IF(J10="اظهارنامه با ارز از مسیر دوبی","اقدام: تبدیل منشأ به دلار دوبی، ثبت اردر اظهارنامه با ارز از مسیر دوبی و هماهنگی ورود ارز.","اقدام: هماهنگی با تأمین‌کننده مستقیم استانبول و دریافت تأیید کارمزد ثابت.")) -> اقدام: تبدیل منشأ به دلار دوبی، ثبت اردر اظهارنامه با ارز از مسیر دوبی و هماهنگی ورود ارز. | Q10: ="- "&B10&": "&J10&" | هزینه "&TEXT(K10,"0.00%")&" | صرفه نسبت به گزینه بعدی "&TEXT(M10,"0.00%") -> - درهم دوبی: اظهارنامه با ارز از مسیر دوبی | هزینه 0.50% | صرفه نسبت به گزینه بعدی 0.47%
A12: Daily Narrative Summary
A13: ="گزارش تصمیم‌سازی روزانه رفع تعهد / اظهارنامه"&CHAR(10)&"تاریخ: "&$B$2&CHAR(10)&"مبلغ مبنا برای محاسبه هزینه دلاری: "&TEXT($B$3,"#,##0")&" دلار"&CHAR(10)&CHAR(10)&Q6&CHAR(10)&Q7&CHAR(10)&Q8&CHAR(10)&Q9&CHAR(10)&Q10&CHAR(10)&CHAR(10)&"جمع‌بندی: جدول بالا همه منشأهای ارزی را با سه مسیر فعال مقایسه می‌کند: اظهارنامه بدون ارز، اظهارنامه با ارز از مسیر دوبی، و مسیر مستقیم استانبول در صورت فعال بودن." -> گزارش تصمیم‌سازی روزانه رفع تعهد / اظهارنامه تاریخ: -180686 مبلغ مبنا برای محاسبه هزینه دلاری: 1,000,000 دلار - دلار تهران: اظهارنامه با ارز از مسیر دوبی | هزینه 0.50% | صرفه نسبت به گزینه بعدی 0.20% - دلار استانبول: اظهارنامه با ارز از مسیر دوبی | هزینه 0.50% | صرفه نسبت به گزینه بعدی 0.09% - دلار سلیمانیه: اظهارنامه با ارز از مسیر دوبی | هزینه 0.50% | صرفه نسبت به گزینه بعدی 0.20% - دلار تتر: اظهارنامه با ارز از مسیر دوبی | هزینه 0.50% | صرفه نسبت به گزینه بعدی 0.47% - درهم دوبی: اظهارنامه با ارز از مسیر دوبی | هزینه 0.50% | صرفه نسبت به گزینه بعدی 0.47% جمع‌بندی: جدول بالا همه منشأهای ارزی را با سه مسیر فعال مقایسه می‌کند: اظهارنامه بدون ارز، اظهارنامه با ارز از مسیر دوبی، و مسیر مستقیم استانبول در صورت فعال بودن.
A15: History Copy Block — copy A17:Y21 and paste VALUES into History starting at A5
A16: Date | B16: Origin Code | C16: Origin Label | D16: Best Route | E16: Best Cost % | F16: Cost Amount USD | G16: No-FX Conv % | H16: No-FX Total % | I16: Dubai Conv % | J16: Dubai Total % | K16: Istanbul Direct % | L16: Tehran Buy | M16: Tehran Sell | N16: Dubai Buy | O16: Dubai Sell | P16: Istanbul Buy | Q16: Istanbul Sell | R16: Sulaymaniyah Buy | S16: Sulaymaniyah Sell | T16: Tether Buy | U16: Tether Sell | V16: No-FX Fee % | W16: Dubai Transfer Fee % | X16: Istanbul Direct Fee % | Y16: Notes
A17: =$B$2 -> -180686 | B17: =A6 -> USD_Tehran | C17: =B6 -> دلار تهران | D17: =J6 -> اظهارنامه با ارز از مسیر دوبی | E17: =K6 -> 0.005 | F17: =N6 -> 5000 | G17: =C6 -> 0 | H17: =E6 -> 0.007 | I17: =F6 | J17: =H6 -> 0.005 | K17: =I6 | L17: {=XLOOKUP("Tehran",Daily_Rates!$A:$A,Daily_Rates!$D:$D)} -> 3.665 | M17: {=XLOOKUP("Tehran",Daily_Rates!$A:$A,Daily_Rates!$E:$E)} -> 3.675 | N17: {=XLOOKUP("Dubai",Daily_Rates!$A:$A,Daily_Rates!$D:$D)} -> - | O17: {=XLOOKUP("Dubai",Daily_Rates!$A:$A,Daily_Rates!$E:$E)} -> - | P17: {=XLOOKUP("Istanbul",Daily_Rates!$A:$A,Daily_Rates!$D:$D)} -> 3.679 | Q17: {=XLOOKUP("Istanbul",Daily_Rates!$A:$A,Daily_Rates!$E:$E)} -> 3.685 | R17: {=XLOOKUP("Sulaymaniyah",Daily_Rates!$A:$A,Daily_Rates!$D:$D)} -> - | S17: {=XLOOKUP("Sulaymaniyah",Daily_Rates!$A:$A,Daily_Rates!$E:$E)} -> - | T17: {=XLOOKUP("Tether",Daily_Rates!$A:$A,Daily_Rates!$D:$D)} -> 3.665 | U17: {=XLOOKUP("Tether",Daily_Rates!$A:$A,Daily_Rates!$E:$E)} -> 3.67 | V17: =Fees_Settings!$E$3 -> 0.007 | W17: =Fees_Settings!$E$4 -> 0.005 | X17: =Fees_Settings!$E$5 -> 0.015 | Y17: =O6 -> بهترین مسیر امروز برای رفع تعهد با منشأ ارز دلار تهران، «اظهارنامه با ارز از مسیر دوبی» است. هزینه تمام‌شده این مسیر 0.50% معادل حدود 5,000 دلار است. مشتری بابت تبدیل دلار تهران به دلار دوبی هزینه می‌دهد و 0.50% هزینه انتقال / ورود ارز از مسیر دوبی پرداخت می‌کند؛ بنابراین هزینه نهایی 0.50% می‌شود. گزینه‌های بعدی به ترتیب هزینه: - اظهارنامه بدون ارز: هزینه تمام‌شده 0.70% معادل حدود 7,000 دلار. - اظهارنامه با ارز مستقیم استانبول: هزینه تمام‌شده معادل حدود 0 دلار. اختلاف بهترین مسیر با نزدیک‌ترین گزینه بعدی 0.20% معادل حدود 2,000 دلار است.
A18: =$B$2 -> -180686 | B18: =A7 -> USD_Istanbul | C18: =B7 -> دلار استانبول | D18: =J7 -> اظهارنامه با ارز از مسیر دوبی | E18: =K7 -> 0.005 | F18: =N7 -> 5000 | G18: =C7 -> -0.001087252 | H18: =E7 -> 0.005912748 | I18: =F7 | J18: =H7 -> 0.005 | K18: =I7 -> 0.015 | L18: {=XLOOKUP("Tehran",Daily_Rates!$A:$A,Daily_Rates!$D:$D)} -> 3.665 | M18: {=XLOOKUP("Tehran",Daily_Rates!$A:$A,Daily_Rates!$E:$E)} -> 3.675 | N18: {=XLOOKUP("Dubai",Daily_Rates!$A:$A,Daily_Rates!$D:$D)} -> - | O18: {=XLOOKUP("Dubai",Daily_Rates!$A:$A,Daily_Rates!$E:$E)} -> - | P18: {=XLOOKUP("Istanbul",Daily_Rates!$A:$A,Daily_Rates!$D:$D)} -> 3.679 | Q18: {=XLOOKUP("Istanbul",Daily_Rates!$A:$A,Daily_Rates!$E:$E)} -> 3.685 | R18: {=XLOOKUP("Sulaymaniyah",Daily_Rates!$A:$A,Daily_Rates!$D:$D)} -> - | S18: {=XLOOKUP("Sulaymaniyah",Daily_Rates!$A:$A,Daily_Rates!$E:$E)} -> - | T18: {=XLOOKUP("Tether",Daily_Rates!$A:$A,Daily_Rates!$D:$D)} -> 3.665 | U18: {=XLOOKUP("Tether",Daily_Rates!$A:$A,Daily_Rates!$E:$E)} -> 3.67 | V18: =Fees_Settings!$E$3 -> 0.007 | W18: =Fees_Settings!$E$4 -> 0.005 | X18: =Fees_Settings!$E$5 -> 0.015 | Y18: =O7 -> بهترین مسیر امروز برای رفع تعهد با منشأ ارز دلار استانبول، «اظهارنامه با ارز از مسیر دوبی» است. هزینه تمام‌شده این مسیر 0.50% معادل حدود 5,000 دلار است. مشتری بابت تبدیل دلار استانبول به دلار دوبی هزینه می‌دهد و 0.50% هزینه انتقال / ورود ارز از مسیر دوبی پرداخت می‌کند؛ بنابراین هزینه نهایی 0.50% می‌شود. گزینه‌های بعدی به ترتیب هزینه: - اظهارنامه بدون ارز: هزینه تمام‌شده 0.59% معادل حدود 5,913 دلار. - اظهارنامه با ارز مستقیم استانبول: هزینه تمام‌شده 1.50% معادل حدود 15,000 دلار. اختلاف بهترین مسیر با نزدیک‌ترین گزینه بعدی 0.09% معادل حدود 913 دلار است.
A19: =$B$2 -> -180686 | B19: =A8 -> USD_Sulaymaniyah | C19: =B8 -> دلار سلیمانیه | D19: =J8 -> اظهارنامه با ارز از مسیر دوبی | E19: =K8 -> 0.005 | F19: =N8 -> 5000 | G19: =C8 | H19: =E8 -> 0.007 | I19: =F8 | J19: =H8 -> 0.005 | K19: =I8 | L19: {=XLOOKUP("Tehran",Daily_Rates!$A:$A,Daily_Rates!$D:$D)} -> 3.665 | M19: {=XLOOKUP("Tehran",Daily_Rates!$A:$A,Daily_Rates!$E:$E)} -> 3.675 | N19: {=XLOOKUP("Dubai",Daily_Rates!$A:$A,Daily_Rates!$D:$D)} -> - | O19: {=XLOOKUP("Dubai",Daily_Rates!$A:$A,Daily_Rates!$E:$E)} -> - | P19: {=XLOOKUP("Istanbul",Daily_Rates!$A:$A,Daily_Rates!$D:$D)} -> 3.679 | Q19: {=XLOOKUP("Istanbul",Daily_Rates!$A:$A,Daily_Rates!$E:$E)} -> 3.685 | R19: {=XLOOKUP("Sulaymaniyah",Daily_Rates!$A:$A,Daily_Rates!$D:$D)} -> - | S19: {=XLOOKUP("Sulaymaniyah",Daily_Rates!$A:$A,Daily_Rates!$E:$E)} -> - | T19: {=XLOOKUP("Tether",Daily_Rates!$A:$A,Daily_Rates!$D:$D)} -> 3.665 | U19: {=XLOOKUP("Tether",Daily_Rates!$A:$A,Daily_Rates!$E:$E)} -> 3.67 | V19: =Fees_Settings!$E$3 -> 0.007 | W19: =Fees_Settings!$E$4 -> 0.005 | X19: =Fees_Settings!$E$5 -> 0.015 | Y19: =O8 -> بهترین مسیر امروز برای رفع تعهد با منشأ ارز دلار سلیمانیه، «اظهارنامه با ارز از مسیر دوبی» است. هزینه تمام‌شده این مسیر 0.50% معادل حدود 5,000 دلار است. مشتری بابت تبدیل دلار سلیمانیه به دلار دوبی هزینه می‌دهد و 0.50% هزینه انتقال / ورود ارز از مسیر دوبی پرداخت می‌کند؛ بنابراین هزینه نهایی 0.50% می‌شود. گزینه‌های بعدی به ترتیب هزینه: - اظهارنامه بدون ارز: هزینه تمام‌شده 0.70% معادل حدود 7,000 دلار. - اظهارنامه با ارز مستقیم استانبول: هزینه تمام‌شده معادل حدود 0 دلار. اختلاف بهترین مسیر با نزدیک‌ترین گزینه بعدی 0.20% معادل حدود 2,000 دلار است.
A20: =$B$2 -> -180686 | B20: =A9 -> USD_Tether | C20: =B9 -> دلار تتر | D20: =J9 -> اظهارنامه با ارز از مسیر دوبی | E20: =K9 -> 0.005 | F20: =N9 -> 5000 | G20: =C9 -> 0.002728513 | H20: =E9 -> 0.009728513 | I20: =F9 | J20: =H9 -> 0.005 | K20: =I9 | L20: {=XLOOKUP("Tehran",Daily_Rates!$A:$A,Daily_Rates!$D:$D)} -> 3.665 | M20: {=XLOOKUP("Tehran",Daily_Rates!$A:$A,Daily_Rates!$E:$E)} -> 3.675 | N20: {=XLOOKUP("Dubai",Daily_Rates!$A:$A,Daily_Rates!$D:$D)} -> - | O20: {=XLOOKUP("Dubai",Daily_Rates!$A:$A,Daily_Rates!$E:$E)} -> - | P20: {=XLOOKUP("Istanbul",Daily_Rates!$A:$A,Daily_Rates!$D:$D)} -> 3.679 | Q20: {=XLOOKUP("Istanbul",Daily_Rates!$A:$A,Daily_Rates!$E:$E)} -> 3.685 | R20: {=XLOOKUP("Sulaymaniyah",Daily_Rates!$A:$A,Daily_Rates!$D:$D)} -> - | S20: {=XLOOKUP("Sulaymaniyah",Daily_Rates!$A:$A,Daily_Rates!$E:$E)} -> - | T20: {=XLOOKUP("Tether",Daily_Rates!$A:$A,Daily_Rates!$D:$D)} -> 3.665 | U20: {=XLOOKUP("Tether",Daily_Rates!$A:$A,Daily_Rates!$E:$E)} -> 3.67 | V20: =Fees_Settings!$E$3 -> 0.007 | W20: =Fees_Settings!$E$4 -> 0.005 | X20: =Fees_Settings!$E$5 -> 0.015 | Y20: =O9 -> بهترین مسیر امروز برای رفع تعهد با منشأ ارز دلار تتر، «اظهارنامه با ارز از مسیر دوبی» است. هزینه تمام‌شده این مسیر 0.50% معادل حدود 5,000 دلار است. مشتری بابت تبدیل دلار تتر به دلار دوبی هزینه می‌دهد و 0.50% هزینه انتقال / ورود ارز از مسیر دوبی پرداخت می‌کند؛ بنابراین هزینه نهایی 0.50% می‌شود. گزینه‌های بعدی به ترتیب هزینه: - اظهارنامه بدون ارز: هزینه تمام‌شده 0.97% معادل حدود 9,729 دلار. - اظهارنامه با ارز مستقیم استانبول: هزینه تمام‌شده معادل حدود 0 دلار. اختلاف بهترین مسیر با نزدیک‌ترین گزینه بعدی 0.47% معادل حدود 4,729 دلار است.
